Workbook

Sheet LOG SIRE Ventas_1007_062026
A1: Ejercicio | B1: Sociedad | C1: Fecha de documento SAP | D1: CAR SUNAT SAP | E1: CAR SUNAT Archivo | F1: Mensaje | G1: tipo | H1: serie | I1: correlativo | J1: concat | K1: base sap | L1: base sunat | M1: diferencia | N1: igv sap | O1: igv sunat | P1: diferencia | Q1: servicio sap | R1: servicio sunat | S1: diferencia | T1: total sap | U1: total sunat | V1: diferencia
A2: 2026 | B2: 1007 | C2: 01.06.2026 | D2: 2053799558101F8070000001695 | E2: 2053799558101F8070000001695 | F2: Registro OK. | G2: 1 | H2: F807 | I2: 1695 | J2: 1-F807-1695 | K2: =+VLOOKUP(J2,sap!I:N,6,0) -> 54.06 | L2: =+VLOOKUP(J2,sunat!J:O,6,0) -> 54.06 | M2: =+K2-L2 -> 0 | N2: =+VLOOKUP(J2,sap!I:P,8,0) -> 9.74 | O2: =+VLOOKUP(J2,sunat!J:Q,8,0) -> 9.74 | P2: =+N2-O2 -> 0 | Q2: =+VLOOKUP(J2,sap!I:X,16,0) -> 0 | R2: =+VLOOKUP(J2,sunat!J:Y,16,0) -> 0 | S2: =+Q2-R2 -> 0 | T2: =+VLOOKUP(J2,sap!I:Y,17,0) -> 63.8 | U2: =+VLOOKUP(J2,sunat!J:Z,17,0) -> 63.8 | V2: =+T2-U2 -> 0
A3: 2026 | B3: 1007 | C3: 01.06.2026 | D3: 2053799558101F8070000001696 | E3: 2053799558101F8070000001696 | F3: Registro OK. | G3: 1 | H3: F807 | I3: 1696 | J3: 1-F807-1696 | K3: =+VLOOKUP(J3,sap!I:N,6,0) -> 192.29 | L3: =+VLOOKUP(J3,sunat!J:O,6,0) -> 192.29 | M3: =+K3-L3 -> 0 | N3: =+VLOOKUP(J3,sap!I:P,8,0) -> 34.61 | O3: =+VLOOKUP(J3,sunat!J:Q,8,0) -> 34.61 | P3: =+N3-O3 -> 0 | Q3: =+VLOOKUP(J3,sap!I:X,16,0) -> 0 | R3: =+VLOOKUP(J3,sunat!J:Y,16,0) -> 0 | S3: =+Q3-R3 -> 0 | T3: =+VLOOKUP(J3,sap!I:Y,17,0) -> 226.9 | U3: =+VLOOKUP(J3,sunat!J:Z,17,0) -> 226.9 | V3: =+T3-U3 -> 0
A4: 2026 | B4: 1007 | C4: 01.06.2026 | D4: 2053799558101F8070000001697 | E4: 2053799558101F8070000001697 | F4: Registro OK. | G4: 1 | H4: F807 | I4: 1697 | J4: 1-F807-1697 | K4: =+VLOOKUP(J4,sap!I:N,6,0) -> 31.27 | L4: =+VLOOKUP(J4,sunat!J:O,6,0) -> 31.27 | M4: =+K4-L4 -> 0 | N4: =+VLOOKUP(J4,sap!I:P,8,0) -> 5.63 | O4: =+VLOOKUP(J4,sunat!J:Q,8,0) -> 5.63 | P4: =+N4-O4 -> 0 | Q4: =+VLOOKUP(J4,sap!I:X,16,0) -> 0 | R4: =+VLOOKUP(J4,sunat!J:Y,16,0) -> 0 | S4: =+Q4-R4 -> 0 | T4: =+VLOOKUP(J4,sap!I:Y,17,0) -> 36.9 | U4: =+VLOOKUP(J4,sunat!J:Z,17,0) -> 36.9 | V4: =+T4-U4 -> 0
A5: 2026 | B5: 1007 | C5: 01.06.2026 | D5: 2053799558101F8050000000889 | E5: 2053799558101F8050000000889 | F5: Registro OK. | G5: 1 | H5: F805 | I5: 889 | J5: 1-F805-889 | K5: =+VLOOKUP(J5,sap!I:N,6,0) -> 304.24 | L5: =+VLOOKUP(J5,sunat!J:O,6,0) -> 304.24 | M5: =+K5-L5 -> 0 | N5: =+VLOOKUP(J5,sap!I:P,8,0) -> 54.76 | O5: =+VLOOKUP(J5,sunat!J:Q,8,0) -> 54.76 | P5: =+N5-O5 -> 0 | Q5: =+VLOOKUP(J5,sap!I:X,16,0) -> 0 | R5: =+VLOOKUP(J5,sunat!J:Y,16,0) -> 0 | S5: =+Q5-R5 -> 0 | T5: =+VLOOKUP(J5,sap!I:Y,17,0) -> 359 | U5: =+VLOOKUP(J5,sunat!J:Z,17,0) -> 359 | V5: =+T5-U5 -> 0
A6: 2026 | B6: 1007 | C6: 01.06.2026 | D6: 2053799558101F8050000000890 | E6: 2053799558101F8050000000890 | F6: Registro OK. | G6: 1 | H6: F805 | I6: 890 | J6: 1-F805-890 | K6: =+VLOOKUP(J6,sap!I:N,6,0) -> 44.06 | L6: =+VLOOKUP(J6,sunat!J:O,6,0) -> 44.06 | M6: =+K6-L6 -> 0 | N6: =+VLOOKUP(J6,sap!I:P,8,0) -> 7.93 | O6: =+VLOOKUP(J6,sunat!J:Q,8,0) -> 7.93 | P6: =+N6-O6 -> 0 | Q6: =+VLOOKUP(J6,sap!I:X,16,0) -> 4.41 | R6: =+VLOOKUP(J6,sunat!J:Y,16,0) -> 4.41 | S6: =+Q6-R6 -> 0 | T6: =+VLOOKUP(J6,sap!I:Y,17,0) -> 56.4 | U6: =+VLOOKUP(J6,sunat!J:Z,17,0) -> 56.4 | V6: =+T6-U6 -> 0
A7: 2026 | B7: 1007 | C7: 01.06.2026 | D7: 2053799558101F8070000001698 | E7: 2053799558101F8070000001698 | F7: Registro OK. | G7: 1 | H7: F807 | I7: 1698 | J7: 1-F807-1698 | K7: =+VLOOKUP(J7,sap!I:N,6,0) -> 135.51 | L7: =+VLOOKUP(J7,sunat!J:O,6,0) -> 135.51 | M7: =+K7-L7 -> 0 | N7: =+VLOOKUP(J7,sap!I:P,8,0) -> 24.39 | O7: =+VLOOKUP(J7,sunat!J:Q,8,0) -> 24.39 | P7: =+N7-O7 -> 0 | Q7: =+VLOOKUP(J7,sap!I:X,16,0) -> 0 | R7: =+VLOOKUP(J7,sunat!J:Y,16,0) -> 0 | S7: =+Q7-R7 -> 0 | T7: =+VLOOKUP(J7,sap!I:Y,17,0) -> 159.9 | U7: =+VLOOKUP(J7,sunat!J:Z,17,0) -> 159.9 | V7: =+T7-U7 -> 0
A8: 2026 | B8: 1007 | C8: 01.06.2026 | D8: 2053799558101F8070000001699 | E8: 2053799558101F8070000001699 | F8: Registro OK. | G8: 1 | H8: F807 | I8: 1699 | J8: 1-F807-1699 | K8: =+VLOOKUP(J8,sap!I:N,6,0) -> 82.54 | L8: =+VLOOKUP(J8,sunat!J:O,6,0) -> 82.54 | M8: =+K8-L8 -> 0 | N8: =+VLOOKUP(J8,sap!I:P,8,0) -> 14.86 | O8: =+VLOOKUP(J8,sunat!J:Q,8,0) -> 14.86 | P8: =+N8-O8 -> 0 | Q8: =+VLOOKUP(J8,sap!I:X,16,0) -> 0 | R8: =+VLOOKUP(J8,sunat!J:Y,16,0) -> 0 | S8: =+Q8-R8 -> 0 | T8: =+VLOOKUP(J8,sap!I:Y,17,0) -> 97.4 | U8: =+VLOOKUP(J8,sunat!J:Z,17,0) -> 97.4 | V8: =+T8-U8 -> 0
A9: 2026 | B9: 1007 | C9: 01.06.2026 | D9: 2053799558101F8060000001979 | E9: 2053799558101F8060000001979 | F9: Registro OK. | G9: 1 | H9: F806 | I9: 1979 | J9: 1-F806-1979 | K9: =+VLOOKUP(J9,sap!I:N,6,0) -> 90.24 | L9: =+VLOOKUP(J9,sunat!J:O,6,0) -> 90.24 | M9: =+K9-L9 -> 0 | N9: =+VLOOKUP(J9,sap!I:P,8,0) -> 16.24 | O9: =+VLOOKUP(J9,sunat!J:Q,8,0) -> 16.24 | P9: =+N9-O9 -> 0 | Q9: =+VLOOKUP(J9,sap!I:X,16,0) -> 9.03 | R9: =+VLOOKUP(J9,sunat!J:Y,16,0) -> 9.03 | S9: =+Q9-R9 -> 0 | T9: =+VLOOKUP(J9,sap!I:Y,17,0) -> 115.51 | U9: =+VLOOKUP(J9,sunat!J:Z,17,0) -> 115.5 | V9: =+T9-U9 -> 0.01
A10: 2026 | B10: 1007 | C10: 01.06.2026 | D10: 2053799558103B8070000025132 | E10: 2053799558103B8070000025132 | F10: Registro OK. | G10: 3 | H10: B807 | I10: 25132 | J10: 3-B807-25132 | K10: =+VLOOKUP(J10,sap!I:N,6,0) -> 0 | L10: =+VLOOKUP(J10,sunat!J:O,6,0) -> 0 | M10: =+K10-L10 -> 0 | N10: =+VLOOKUP(J10,sap!I:P,8,0) -> 0 | O10: =+VLOOKUP(J10,sunat!J:Q,8,0) -> 0 | P10: =+N10-O10 -> 0 | Q10: =+VLOOKUP(J10,sap!I:X,16,0) -> 0 | R10: =+VLOOKUP(J10,sunat!J:Y,16,0) -> 0 | S10: =+Q10-R10 -> 0 | T10: =+VLOOKUP(J10,sap!I:Y,17,0) -> 0 | U10: =+VLOOKUP(J10,sunat!J:Z,17,0) -> 0 | V10: =+T10-U10 -> 0
A11: 2026 | B11: 1007 | C11: 01.06.2026 | D11: 2053799558103B8070000025133 | E11: 2053799558103B8070000025133 | F11: Registro OK. | G11: 3 | H11: B807 | I11: 25133 | J11: 3-B807-25133 | K11: =+VLOOKUP(J11,sap!I:N,6,0) -> 27.88 | L11: =+VLOOKUP(J11,sunat!J:O,6,0) -> 27.88 | M11: =+K11-L11 -> 0 | N11: =+VLOOKUP(J11,sap!I:P,8,0) -> 5.02 | O11: =+VLOOKUP(J11,sunat!J:Q,8,0) -> 5.02 | P11: =+N11-O11 -> 0 | Q11: =+VLOOKUP(J11,sap!I:X,16,0) -> 0 | R11: =+VLOOKUP(J11,sunat!J:Y,16,0) -> 0 | S11: =+Q11-R11 -> 0 | T11: =+VLOOKUP(J11,sap!I:Y,17,0) -> 32.9 | U11: =+VLOOKUP(J11,sunat!J:Z,17,0) -> 32.9 | V11: =+T11-U11 -> 0
A12: 2026 | B12: 1007 | C12: 01.06.2026 | D12: 2053799558103B8070000025134 | E12: 2053799558103B8070000025134 | F12: Registro OK. | G12: 3 | H12: B807 | I12: 25134 | J12: 3-B807-25134 | K12: =+VLOOKUP(J12,sap!I:N,6,0) -> 30.08 | L12: =+VLOOKUP(J12,sunat!J:O,6,0) -> 30.08 | M12: =+K12-L12 -> 0 | N12: =+VLOOKUP(J12,sap!I:P,8,0) -> 5.42 | O12: =+VLOOKUP(J12,sunat!J:Q,8,0) -> 5.42 | P12: =+N12-O12 -> 0 | Q12: =+VLOOKUP(J12,sap!I:X,16,0) -> 0 | R12: =+VLOOKUP(J12,sunat!J:Y,16,0) -> 0 | S12: =+Q12-R12 -> 0 | T12: =+VLOOKUP(J12,sap!I:Y,17,0) -> 35.5 | U12: =+VLOOKUP(J12,sunat!J:Z,17,0) -> 35.5 | V12: =+T12-U12 -> 0
A13: 2026 | B13: 1007 | C13: 01.06.2026 | D13: 2053799558103B8070000025135 | E13: 2053799558103B8070000025135 | F13: Registro OK. | G13: 3 | H13: B807 | I13: 25135 | J13: 3-B807-25135 | K13: =+VLOOKUP(J13,sap!I:N,6,0) -> 35.93 | L13: =+VLOOKUP(J13,sunat!J:O,6,0) -> 35.93 | M13: =+K13-L13 -> 0 | N13: =+VLOOKUP(J13,sap!I:P,8,0) -> 6.47 | O13: =+VLOOKUP(J13,sunat!J:Q,8,0) -> 6.47 | P13: =+N13-O13 -> 0 | Q13: =+VLOOKUP(J13,sap!I:X,16,0) -> 0 | R13: =+VLOOKUP(J13,sunat!J:Y,16,0) -> 0 | S13: =+Q13-R13 -> 0 | T13: =+VLOOKUP(J13,sap!I:Y,17,0) -> 42.4 | U13: =+VLOOKUP(J13,sunat!J:Z,17,0) -> 42.4 | V13: =+T13-U13 -> 0
... A4354: 2026 | B4354: 1007 | C4354: 24.06.2026 | D4354: 2053799558101F8050000000974 | E4354: 2053799558101F8050000000974 | F4354: Registro OK. | G4354: 1 | H4354: F805 | I4354: 974 | J4354: 1-F805-974 | K4354: =+VLOOKUP(J4354,sap!I:N,6,0) -> 57.59 | L4354: =+VLOOKUP(J4354,sunat!J:O,6,0) -> 57.59 | M4354: =+K4354-L4354 -> 0 | N4354: =+VLOOKUP(J4354,sap!I:P,8,0) -> 10.36 | O4354: =+VLOOKUP(J4354,sunat!J:Q,8,0) -> 10.36 | P4354: =+N4354-O4354 -> 0 | Q4354: =+VLOOKUP(J4354,sap!I:X,16,0) -> 5.76 | R4354: =+VLOOKUP(J4354,sunat!J:Y,16,0) -> 5.76 | S4354: =+Q4354-R4354 -> 0 | T4354: =+VLOOKUP(J4354,sap!I:Y,17,0) -> 73.71 | U4354: =+VLOOKUP(J4354,sunat!J:Z,17,0) -> 73.7 | V4354: =+T4354-U4354 -> 0.01
A4355: 2026 | B4355: 1007 | C4355: 16.06.2026 | D4355: 2053799558101FE010000001223 | F4355: No existe en SUNAT. | G4355: 1 | H4355: FE01 | I4355: 1223 | J4355: 1-FE01-1223 | K4355: =+VLOOKUP(J4355,sap!I:N,6,0) -> 0 | L4355: =+VLOOKUP(J4355,sunat!J:O,6,0) -> #N/A | M4355: =+K4355-L4355 -> #N/A | N4355: =+VLOOKUP(J4355,sap!I:P,8,0) -> 0 | O4355: =+VLOOKUP(J4355,sunat!J:Q,8,0) -> #N/A | P4355: =+N4355-O4355 -> #N/A | Q4355: =+VLOOKUP(J4355,sap!I:X,16,0) -> 0 | R4355: =+VLOOKUP(J4355,sunat!J:Y,16,0) -> #N/A | S4355: =+Q4355-R4355 -> #N/A | T4355: =+VLOOKUP(J4355,sap!I:Y,17,0) -> 0 | U4355: =+VLOOKUP(J4355,sunat!J:Z,17,0) -> #N/A | V4355: =+T4355-U4355 -> #N/A
A4356: 2026 | B4356: 1007 | C4356: 17.06.2026 | D4356: 2053799558103BE010000000239 | F4356: No existe en SUNAT. | G4356: 3 | H4356: BE01 | I4356: 239 | J4356: 3-BE01-239 | K4356: =+VLOOKUP(J4356,sap!I:N,6,0) -> 0 | L4356: =+VLOOKUP(J4356,sunat!J:O,6,0) -> #N/A | M4356: =+K4356-L4356 -> #N/A | N4356: =+VLOOKUP(J4356,sap!I:P,8,0) -> 0 | O4356: =+VLOOKUP(J4356,sunat!J:Q,8,0) -> #N/A | P4356: =+N4356-O4356 -> #N/A | Q4356: =+VLOOKUP(J4356,sap!I:X,16,0) -> 0 | R4356: =+VLOOKUP(J4356,sunat!J:Y,16,0) -> #N/A | S4356: =+Q4356-R4356 -> #N/A | T4356: =+VLOOKUP(J4356,sap!I:Y,17,0) -> 0 | U4356: =+VLOOKUP(J4356,sunat!J:Z,17,0) -> #N/A | V4356: =+T4356-U4356 -> #N/A

Sheet sunat
A1: Ruc | B1: Razon Social | C1: Periodo | D1: CAR SUNAT | E1: Fecha de emisión | F1: Fecha Vcto/Pago | G1: Tipo CP/Doc. | H1: Serie del CDP | I1: Nro CP o Doc. Nro Inicial (Rango) | J1: Nro Final (Rango) | K1: Tipo Doc Identidad | L1: Nro Doc Identidad | M1: Apellidos Nombres/ Razón Social | N1: Valor Facturado Exportación | O1: BI Gravada | P1: Dscto BI | Q1: IGV / IPM | R1: Dscto IGV / IPM | S1: Mto Exonerado | T1: Mto Inafecto | U1: ISC | V1: BI Grav IVAP | W1: IVAP | X1: ICBPER | Y1: Otros Tributos | Z1: Total CP | AA1: Moneda | AB1: Tipo Cambio | AC1: Fecha Emisión Doc Modificado | AD1: Tipo CP Modificado | AE1: Serie CP Modificado | AF1: Nro CP Modificado | AG1: ID Proyecto Operadores Atribución | AH1: Tipo de Nota | AI1: Est. Comp | AJ1: Valor FOB Embarcado | AK1: Valor OP Gratuitas | AL1: Tipo Operación | AM1: DAM / CP | AN1: CLU
A2: 20537995581 | B2: INVERSIONES M5 S.A.C. | C2: 202606 | D2: 2053799558101F8070000001695 | E2: 46174 | G2: 1 | H2: F807 | I2: 1695 | J2: 1-F807-1695 | K2: 6 | L2: 20500985322 | M2: MACHU PICCHU FOODS SAC | N2: 0 | O2: 54.06 | P2: 0 | Q2: 9.74 | R2: 0 | S2: 0 | T2: 0 | U2: 0 | V2: 0 | W2: 0 | X2: 0 | Y2: 0 | Z2: 63.8 | AA2: PEN | AB2: 1 | AI2: 1 | AJ2: 0 | AK2: 0 | AL2: 101
A3: 20537995581 | B3: INVERSIONES M5 S.A.C. | C3: 202606 | D3: 2053799558101F8070000001696 | E3: 46174 | G3: 1 | H3: F807 | I3: 1696 | J3: 1-F807-1696 | K3: 6 | L3: 20521626021 | M3: CENTER QUIMICA SAC | N3: 0 | O3: 192.29 | P3: 0 | Q3: 34.61 | R3: 0 | S3: 0 | T3: 0 | U3: 0 | V3: 0 | W3: 0 | X3: 0 | Y3: 0 | Z3: 226.9 | AA3: PEN | AB3: 1 | AI3: 1 | AJ3: 0 | AK3: 0 | AL3: 101
A4: 20537995581 | B4: INVERSIONES M5 S.A.C. | C4: 202606 | D4: 2053799558101F8070000001697 | E4: 46174 | G4: 1 | H4: F807 | I4: 1697 | J4: 1-F807-1697 | K4: 6 | L4: 10473031383 | M4: STEFANY PORTUGUEZ | N4: 0 | O4: 31.27 | P4: 0 | Q4: 5.63 | R4: 0 | S4: 0 | T4: 0 | U4: 0 | V4: 0 | W4: 0 | X4: 0 | Y4: 0 | Z4: 36.9 | AA4: PEN | AB4: 1 | AI4: 1 | AJ4: 0 | AK4: 0 | AL4: 101
A5: 20537995581 | B5: INVERSIONES M5 S.A.C. | C5: 202606 | D5: 2053799558101F8050000000889 | E5: 46174 | G5: 1 | H5: F805 | I5: 889 | J5: 1-F805-889 | K5: 6 | L5: 20342868844 | M5: STAR UP SAC | N5: 0 | O5: 304.24 | P5: 0 | Q5: 54.76 | R5: 0 | S5: 0 | T5: 0 | U5: 0 | V5: 0 | W5: 0 | X5: 0 | Y5: 0 | Z5: 359 | AA5: PEN | AB5: 1 | AI5: 1 | AJ5: 0 | AK5: 0 | AL5: 101
A6: 20537995581 | B6: INVERSIONES M5 S.A.C. | C6: 202606 | D6: 2053799558101F8050000000890 | E6: 46174 | G6: 1 | H6: F805 | I6: 890 | J6: 1-F805-890 | K6: 6 | L6: 10438444047 | M6: AGUILAR VARGAS MIRIAM MILAGROS | N6: 0 | O6: 44.06 | P6: 0 | Q6: 7.93 | R6: 0 | S6: 0 | T6: 0 | U6: 0 | V6: 0 | W6: 0 | X6: 0 | Y6: 4.41 | Z6: 56.4 | AA6: PEN | AB6: 1 | AI6: 1 | AJ6: 0 | AK6: 0 | AL6: 101
A7: 20537995581 | B7: INVERSIONES M5 S.A.C. | C7: 202606 | D7: 2053799558101F8070000001698 | E7: 46174 | G7: 1 | H7: F807 | I7: 1698 | J7: 1-F807-1698 | K7: 6 | L7: 20100039207 | M7: RANSA COMERCIAL SAC | N7: 0 | O7: 135.51 | P7: 0 | Q7: 24.39 | R7: 0 | S7: 0 | T7: 0 | U7: 0 | V7: 0 | W7: 0 | X7: 0 | Y7: 0 | Z7: 159.9 | AA7: PEN | AB7: 1 | AI7: 1 | AJ7: 0 | AK7: 0 | AL7: 101
A8: 20537995581 | B8: INVERSIONES M5 S.A.C. | C8: 202606 | D8: 2053799558101F8070000001699 | E8: 46174 | G8: 1 | H8: F807 | I8: 1699 | J8: 1-F807-1699 | K8: 6 | L8: 20100055237 | M8: ALICORP SAA | N8: 0 | O8: 82.54 | P8: 0 | Q8: 14.86 | R8: 0 | S8: 0 | T8: 0 | U8: 0 | V8: 0 | W8: 0 | X8: 0 | Y8: 0 | Z8: 97.4 | AA8: PEN | AB8: 1 | AI8: 1 | AJ8: 0 | AK8: 0 | AL8: 101
A9: 20537995581 | B9: INVERSIONES M5 S.A.C. | C9: 202606 | D9: 2053799558101F8060000001979 | E9: 46174 | G9: 1 | H9: F806 | I9: 1979 | J9: 1-F806-1979 | K9: 6 | L9: 10728953174 | M9: UBALDO SANCHEZ JEAN PIERR DAVID | N9: 0 | O9: 90.24 | P9: 0 | Q9: 16.24 | R9: 0 | S9: 0 | T9: 0 | U9: 0 | V9: 0 | W9: 0 | X9: 0 | Y9: 9.03 | Z9: 115.5 | AA9: PEN | AB9: 1 | AI9: 1 | AJ9: 0 | AK9: 0 | AL9: 101
A10: 20537995581 | B10: INVERSIONES M5 S.A.C. | C10: 202606 | D10: 2053799558103B8070000025132 | E10: 46174 | G10: 3 | H10: B807 | I10: 25132 | J10: 3-B807-25132 | K10: 1 | L10: 42500543 | M10: MAGALY RODRIGUEZ | N10: 0 | O10: 0 | P10: 0 | Q10: 0 | R10: 0 | S10: 0 | T10: 0 | U10: 0 | V10: 0 | W10: 0 | X10: 0 | Y10: 0 | Z10: 0 | AA10: PEN | AB10: 0 | AI10: 2 | AJ10: 0 | AK10: 0 | AL10: 101
A11: 20537995581 | B11: INVERSIONES M5 S.A.C. | C11: 202606 | D11: 2053799558103B8070000025133 | E11: 46174 | G11: 3 | H11: B807 | I11: 25133 | J11: 3-B807-25133 | K11: 1 | L11: 11111111 | M11: CLIENTE GENERICO | N11: 0 | O11: 27.88 | P11: 0 | Q11: 5.02 | R11: 0 | S11: 0 | T11: 0 | U11: 0 | V11: 0 | W11: 0 | X11: 0 | Y11: 0 | Z11: 32.9 | AA11: PEN | AB11: 1 | AI11: 1 | AJ11: 0 | AK11: 0 | AL11: 101
A12: 20537995581 | B12: INVERSIONES M5 S.A.C. | C12: 202606 | D12: 2053799558103B8070000025134 | E12: 46174 | G12: 3 | H12: B807 | I12: 25134 | J12: 3-B807-25134 | K12: 1 | L12: 0 | M12: CLIENTE GENERICO | N12: 0 | O12: 30.08 | P12: 0 | Q12: 5.42 | R12: 0 | S12: 0 | T12: 0 | U12: 0 | V12: 0 | W12: 0 | X12: 0 | Y12: 0 | Z12: 35.5 | AA12: PEN | AB12: 1 | AI12: 1 | AJ12: 0 | AK12: 0 | AL12: 101
A13: 20537995581 | B13: INVERSIONES M5 S.A.C. | C13: 202606 | D13: 2053799558103B8070000025135 | E13: 46174 | G13: 3 | H13: B807 | I13: 25135 | J13: 3-B807-25135 | K13: 1 | L13: 0 | M13: CLIENTE GENERICO | N13: 0 | O13: 35.93 | P13: 0 | Q13: 6.47 | R13: 0 | S13: 0 | T13: 0 | U13: 0 | V13: 0 | W13: 0 | X13: 0 | Y13: 0 | Z13: 42.4 | AA13: PEN | AB13: 1 | AI13: 1 | AJ13: 0 | AK13: 0 | AL13: 101
... A4395: 20537995581 | B4395: INVERSIONES M5 S.A.C. | C4395: 202606 | D4395: 2053799558103B8050000011072 | E4395: 46198 | G4395: 3 | H4395: B805 | I4395: 11072 | J4395: 3-B805-11072 | K4395: 1 | L4395: 0 | M4395: CLIENTE GENERICO | N4395: 0 | O4395: 42.29 | P4395: 0 | Q4395: 7.61 | R4395: 0 | S4395: 0 | T4395: 0 | U4395: 0 | V4395: 0 | W4395: 0 | X4395: 0 | Y4395: 0 | Z4395: 49.9 | AA4395: PEN | AB4395: 1 | AI4395: 1 | AJ4395: 0 | AK4395: 0 | AL4395: 101

Sheet sap
J1: g
A2: 20260600 | B2: 1800027676 | C2: M000 | D2: 46174 | E2: 46174 | F2: 1 | G2: F805 | H2: 889 | I2: 1-F805-889 | J2: 6 | K2: 20342868844 | L2: STAR UP S A C | M2: 0 | N2: 304.24 | P2: 54.76 | R2: 0 | S2: 0 | T2: 0 | U2: 0 | V2: 0 | W2: 0 | X2: 0 | Y2: 359 | AB2: 01/01/0001 | AC2: 0 | AD2: - | AE2: - | AI2: 1
A3: 20260600 | B3: 1800027677 | C3: M000 | D3: 46174 | E3: 46174 | F3: 1 | G3: F805 | H3: 890 | I3: 1-F805-890 | J3: 6 | K3: 10438444047 | L3: AGUILAR VARGAS MIRIAM MILAGROS | M3: 0 | N3: 44.06 | P3: 7.93 | R3: 0 | S3: 0 | T3: 0 | U3: 0 | V3: 0 | W3: 0 | X3: 4.41 | Y3: 56.4 | AB3: 01/01/0001 | AC3: 0 | AD3: - | AE3: - | AI3: 1
A4: 20260600 | B4: 1800027808 | C4: M000 | D4: 46175 | E4: 46175 | F4: 1 | G4: F805 | H4: 891 | I4: 1-F805-891 | J4: 6 | K4: 20554893784 | L4: CRAFT MULTIMODAL PERU SOCIEDAD ANON | M4: 0 | N4: 104.06 | P4: 18.74 | R4: 0 | S4: 0 | T4: 0 | U4: 0 | V4: 0 | W4: 0 | X4: 0 | Y4: 122.8 | AB4: 01/01/0001 | AC4: 0 | AD4: - | AE4: - | AI4: 1
A5: 20260600 | B5: 1800027809 | C5: M000 | D5: 46175 | E5: 46175 | F5: 1 | G5: F805 | H5: 892 | I5: 1-F805-892 | J5: 6 | K5: 20409446303 | L5: UNIDAD EJECUTORA 402 HOSPITAL REGIO | M5: 0 | N5: 87.81 | P5: 15.81 | R5: 0 | S5: 0 | T5: 0 | U5: 0 | V5: 0 | W5: 0 | X5: 8.78 | Y5: 112.4 | AB5: 01/01/0001 | AC5: 0 | AD5: - | AE5: - | AI5: 1
A6: 20260600 | B6: 1800027810 | C6: M000 | D6: 46175 | E6: 46175 | F6: 1 | G6: F805 | H6: 893 | I6: 1-F805-893 | J6: 6 | K6: 20503801575 | L6: RECTIFICACIONES Y FABRICACIONES MEC | M6: 0 | N6: 111.79 | P6: 20.13 | R6: 0 | S6: 0 | T6: 0 | U6: 0 | V6: 0 | W6: 0 | X6: 11.18 | Y6: 143.1 | AB6: 01/01/0001 | AC6: 0 | AD6: - | AE6: - | AI6: 1
A7: 20260600 | B7: 1800027811 | C7: M000 | D7: 46175 | E7: 46175 | F7: 1 | G7: F805 | H7: 894 | I7: 1-F805-894 | J7: 6 | K7: 20614277441 | L7: MYK LOGISTICS S A C | M7: 0 | N7: 71.4 | P7: 12.85 | R7: 0 | S7: 0 | T7: 0 | U7: 0 | V7: 0 | W7: 0 | X7: 7.15 | Y7: 91.4 | AB7: 01/01/0001 | AC7: 0 | AD7: - | AE7: - | AI7: 1
A8: 20260600 | B8: 1800027942 | C8: M000 | D8: 46176 | E8: 46176 | F8: 1 | G8: F805 | H8: 895 | I8: 1-F805-895 | J8: 6 | K8: 10256776931 | L8: PICCO VIEIRA FRANCISCO CAYETANO | M8: 0 | N8: 44.06 | P8: 7.93 | R8: 0 | S8: 0 | T8: 0 | U8: 0 | V8: 0 | W8: 0 | X8: 4.41 | Y8: 56.4 | AB8: 01/01/0001 | AC8: 0 | AD8: - | AE8: - | AI8: 1
A9: 20260600 | B9: 1800027943 | C9: M000 | D9: 46176 | E9: 46176 | F9: 1 | G9: F805 | H9: 896 | I9: 1-F805-896 | J9: 6 | K9: 20556570681 | L9: TRIA PERU SOCIEDAD ANONIMA CERRADA | M9: 0 | N9: 55 | P9: 9.9 | R9: 0 | S9: 0 | T9: 0 | U9: 0 | V9: 0 | W9: 0 | X9: 5.5 | Y9: 70.4 | AB9: 01/01/0001 | AC9: 0 | AD9: - | AE9: - | AI9: 1
A10: 20260600 | B10: 1800027944 | C10: M000 | D10: 46176 | E10: 46176 | F10: 1 | G10: F805 | H10: 897 | I10: 1-F805-897 | J10: 6 | K10: 10256481281 | L10: CHAVARRIA RAMIREZ NICODEMOS | M10: 0 | N10: 67.81 | P10: 12.21 | R10: 0 | S10: 0 | T10: 0 | U10: 0 | V10: 0 | W10: 0 | X10: 6.78 | Y10: 86.8 | AB10: 01/01/0001 | AC10: 0 | AD10: - | AE10: - | AI10: 1
A11: 20260600 | B11: 1800028220 | C11: M000 | D11: 46178 | E11: 46178 | F11: 1 | G11: F805 | H11: 898 | I11: 1-F805-898 | J11: 6 | K11: 10464344531 | L11: POLO APAZA PAUL GIANCARLOS | M11: 0 | N11: 46.41 | P11: 8.35 | R11: 0 | S11: 0 | T11: 0 | U11: 0 | V11: 0 | W11: 0 | X11: 4.64 | Y11: 59.4 | AB11: 01/01/0001 | AC11: 0 | AD11: - | AE11: - | AI11: 1
A12: 20260600 | B12: 1800028221 | C12: M000 | D12: 46178 | E12: 46178 | F12: 1 | G12: F805 | H12: 899 | I12: 1-F805-899 | J12: 6 | K12: 20516017181 | L12: ALBERT ASESORES S A C | M12: 0 | N12: 110.31 | P12: 19.86 | R12: 0 | S12: 0 | T12: 0 | U12: 0 | V12: 0 | W12: 0 | X12: 11.02 | Y12: 141.19 | AB12: 01/01/0001 | AC12: 0 | AD12: - | AE12: - | AI12: 1
A13: 20260600 | B13: 1800028222 | C13: M000 | D13: 46178 | E13: 46178 | F13: 1 | G13: F805 | H13: 900 | I13: 1-F805-900 | J13: 6 | K13: 10705245717 | L13: ABU SHABAB NU EZ NIDAL ADELI | M13: 0 | N13: 64.53 | P13: 11.61 | R13: 0 | S13: 0 | T13: 0 | U13: 0 | V13: 0 | W13: 0 | X13: 6.46 | Y13: 82.6 | AB13: 01/01/0001 | AC13: 0 | AD13: - | AE13: - | AI13: 1
... A45: 20260600 | B45: 1800030203 | C45: M000 | D45: 46188 | E45: 46188 | F45: 1 | G45: F805 | H45: 932 | I45: 1-F805-932 | J45: 6 | K45: 10069908689 | L45: QUISPE RIVERA DE RODRIGUEZ MARTHA E | M45: 0 | N45: 65.32 | P45: 11.76 | R45: 0 | S45: 0 | T45: 0 | U45: 0 | V45: 0 | W45: 0 | X45: 6.52 | Y45: 83.6 | AB45: 01/01/0001 | AC45: 0 | AD45: - | AE45: - | AI45: 1
A46: 20260600 | B46: 01F8050000933 | C46: M000 | D46: 46188 | F46: 1 | G46: F805 | H46: 933 | I46: 1-F805-933 | J46: 0 | K46: 0 | L46: ANULADO | M46: 0 | N46: 0 | P46: 0 | R46: 0 | S46: 0 | T46: 0 | U46: 0 | V46: 0 | W46: 0 | X46: 0 | Y46: 0 | AB46: 01/01/0001 | AC46: 0 | AD46: - | AE46: - | AI46: 2
A47: 20260600 | B47: 1800030204 | C47: M000 | D47: 46188 | E47: 46188 | F47: 1 | G47: F805 | H47: 934 | I47: 1-F805-934 | J47: 6 | K47: 20613007637 | L47: MAKERBOX E I R L | M47: 0 | N47: 91.24 | P47: 16.43 | R47: 0 | S47: 0 | T47: 0 | U47: 0 | V47: 0 | W47: 0 | X47: 9.12 | Y47: 116.79 | AB47: 01/01/0001 | AC47: 0 | AD47: - | AE47: - | AI47: 1
A48: 20260600 | B48: 1800030205 | C48: M000 | D48: 46188 | E48: 46188 | F48: 1 | G48: F805 | H48: 935 | I48: 1-F805-935 | J48: 6 | K48: 10091803033 | L48: SANTISTEBAN CUELLAR BRIGIDA | M48: 0 | N48: 44.06 | P48: 7.93 | R48: 0 | S48: 0 | T48: 0 | U48: 0 | V48: 0 | W48: 0 | X48: 4.41 | Y48: 56.4 | AB48: 01/01/0001 | AC48: 0 | AD48: - | AE48: - | AI48: 1
A49: 20260600 | B49: 1800030329 | C49: M000 | D49: 46189 | E49: 46189 | F49: 1 | G49: F805 | H49: 936 | I49: 1-F805-936 | J49: 6 | K49: 20612758302 | L49: BRECH COMPANY E I R L | M49: 0 | N49: 94.46 | P49: 16.99 | R49: 0 | S49: 0 | T49: 0 | U49: 0 | V49: 0 | W49: 0 | X49: 9.45 | Y49: 120.9 | AB49: 01/01/0001 | AC49: 0 | AD49: - | AE49: - | AI49: 1
A50: 20260600 | B50: 1800030330 | C50: M000 | D50: 46189 | E50: 46189 | F50: 1 | G50: F805 | H50: 937 | I50: 1-F805-937 | J50: 6 | K50: 20611163381 | L50: KMMP AMAZON A S A C | M50: 0 | N50: 45.62 | P50: 8.21 | R50: 0 | S50: 0 | T50: 0 | U50: 0 | V50: 0 | W50: 0 | X50: 4.56 | Y50: 58.39 | AB50: 01/01/0001 | AC50: 0 | AD50: - | AE50: - | AI50: 1
A51: 20260600 | B51: 1800030331 | C51: M000 | D51: 46189 | E51: 46189 | F51: 1 | G51: F805 | H51: 938 | I51: 1-F805-938 | J51: 6 | K51: 20554045775 | L51: AISLAMONTAJES CONTRATISTAS GENERALE | M51: 0 | N51: 56.17 | P51: 10.11 | R51: 0 | S51: 0 | T51: 0 | U51: 0 | V51: 0 | W51: 0 | X51: 5.62 | Y51: 71.9 | AB51: 01/01/0001 | AC51: 0 | AD51: - | AE51: - | AI51: 1
A52: 20260600 | B52: 1800030455 | C52: M000 | D52: 46190 | E52: 46190 | F52: 1 | G52: F805 | H52: 939 | I52: 1-F805-939 | J52: 6 | K52: 20498752234 | L52: NAVALES S A C | M52: 0 | N52: 146.64 | P52: 26.4 | R52: 0 | S52: 0 | T52: 0 | U52: 0 | V52: 0 | W52: 0 | X52: 14.66 | Y52: 187.7 | AB52: 01/01/0001 | AC52: 0 | AD52: - | AE52: - | AI52: 1
A53: 20260600 | B53: 1800030456 | C53: M000 | D53: 46190 | E53: 46190 | F53: 1 | G53: F805 | H53: 940 | I53: 1-F805-940 | J53: 6 | K53: 20524194334 | L53: FIELDCORE SERVICE SOLUTIONS INTERNA | M53: 0 | N53: 33.44 | P53: 6.02 | R53: 0 | S53: 0 | T53: 0 | U53: 0 | V53: 0 | W53: 0 | X53: 3.34 | Y53: 42.8 | AB53: 01/01/0001 | AC53: 0 | AD53: - | AE53: - | AI53: 1
A54: 20260600 | B54: 1800030457 | C54: M000 | D54: 46190 | E54: 46190 | F54: 1 | G54: F805 | H54: 941 | I54: 1-F805-941 | J54: 6 | K54: 20519257859 | L54: SERVICIOS GENERALES RAFO S S A C | M54: 0 | N54: 115.79 | P54: 20.83 | R54: 0 | S54: 0 | T54: 0 | U54: 0 | V54: 0 | W54: 0 | X54: 11.57 | Y54: 148.19 | AB54: 01/01/0001 | AC54: 0 | AD54: - | AE54: - | AI54: 1
A55: 20260600 | B55: 1800030458 | C55: M000 | D55: 46190 | E55: 46190 | F55: 1 | G55: F805 | H55: 942 | I55: 1-F805-942 | J55: 6 | K55: 20608098845 | L55: ESPLENDOR LOGISTICS HT S A C | M55: 0 | N55: 432.96 | P55: 77.93 | R55: 0 | S55: 0 | T55: 0 | U55: 0 | V55: 0 | W55: 0 | X55: 43.3 | Y55: 554.19 | AB55: 01/01/0001 | AC55: 0 | AD55: - | AE55: - | AI55: 1
A56: 20260600 | B56: 1800030459 | C56: M000 | D56: 46190 | E56: 46190 | F56: 1 | G56: F805 | H56: 943 | I56: 1-F805-943 | J56: 6 | K56: 20608098845 | L56: ESPLENDOR LOGISTICS HT S A C | M56: 0 | N56: 27.03 | P56: 4.87 | R56: 0 | S56: 0 | T56: 0 | U56: 0 | V56: 0 | W56: 0 | X56: 0 | Y56: 31.9 | AB56: 01/01/0001 | AC56: 0 | AD56: - | AE56: - | AI56: 1
A57: 20260600 | B57: 1800030564 | C57: M000 | D57: 46191 | E57: 46191 | F57: 1 | G57: F805 | H57: 944 | I57: 1-F805-944 | J57: 6 | K57: 20600366948 | L57: DOHWA ENGINEERING CO LTD SUCURSAL D | M57: 0 | N57: 216.09 | P57: 38.9 | R57: 0 | S57: 0 | T57: 0 | U57: 0 | V57: 0 | W57: 0 | X57: 21.61 | Y57: 276.6 | AB57: 01/01/0001 | AC57: 0 | AD57: - | AE57: - | AI57: 1
A58: 20260600 | B58: 1800030565 | C58: M000 | D58: 46191 | E58: 46191 | F58: 1 | G58: F805 | H58: 945 | I58: 1-F805-945 | J58: 6 | K58: 20603628358 | L58: C C OPERADOR LOGISTICO Y TRANSPORTE | M58: 0 | N58: 83.36 | P58: 15 | R58: 0 | S58: 0 | T58: 0 | U58: 0 | V58: 0 | W58: 0 | X58: 8.33 | Y58: 106.69 | AB58: 01/01/0001 | AC58: 0 | AD58: - | AE58: - | AI58: 1
... A226: 20260600 | B226: 1800029154 | C226: M000 | D226: 46182 | E226: 46182 | F226: 1 | G226: F807 | H226: 1745 | I226: 1-F807-1745 | J226: 6 | K226: 20380639522 | L226: BOLIVARIANA DE CARGAS SRL | M226: 0 | N226: 27.88 | P226: 5.02 | R226: 0 | S226: 0 | T226: 0 | U226: 0 | V226: 0 | W226: 0 | X226: 0 | Y226: 32.9 | AB226: 01/01/0001 | AC226: 0 | AD226: - | AE226: - | AI226: 1
A227: 20260600 | B227: 01F8070001746 | C227: M000 | D227: 46183 | F227: 1 | G227: F807 | H227: 1746 | I227: 1-F807-1746 | J227: 0 | K227: 0 | L227: ANULADO | M227: 0 | N227: 0 | P227: 0 | R227: 0 | S227: 0 | T227: 0 | U227: 0 | V227: 0 | W227: 0 | X227: 0 | Y227: 0 | AB227: 01/01/0001 | AC227: 0 | AD227: - | AE227: - | AI227: 2
A228: 20260600 | B228: 1800029294 | C228: M000 | D228: 46183 | E228: 46183 | F228: 1 | G228: F807 | H228: 1747 | I228: 1-F807-1747 | J228: 6 | K228: 15604273886 | L228: MILIUSKA EDWIUMAR HERN NDEZ ANDRADE | M228: 0 | N228: 85.59 | P228: 15.41 | R228: 0 | S228: 0 | T228: 0 | U228: 0 | V228: 0 | W228: 0 | X228: 0 | Y228: 101 | AB228: 01/01/0001 | AC228: 0 | AD228: - | AE228: - | AI228: 1
A229: 20260600 | B229: 1800029295 | C229: M000 | D229: 46183 | E229: 46183 | F229: 1 | G229: F807 | H229: 1748 | I229: 1-F807-1748 | J229: 6 | K229: 20562912534 | L229: TIERRA GROUP INTERNATIONAL SAC | M229: 0 | N229: 39.66 | P229: 7.14 | R229: 0 | S229: 0 | T229: 0 | U229: 0 | V229: 0 | W229: 0 | X229: 0 | Y229: 46.8 | AB229: 01/01/0001 | AC229: 0 | AD229: - | AE229: - | AI229: 1
A230: 20260600 | B230: 1800029296 | C230: M000 | D230: 46183 | E230: 46183 | F230: 1 | G230: F807 | H230: 1749 | I230: 1-F807-1749 | J230: 6 | K230: 20302241598 | L230: KOMATSU MITSUI MAQUINARIAS PER SA | M230: 0 | N230: 54.92 | P230: 9.88 | R230: 0 | S230: 0 | T230: 0 | U230: 0 | V230: 0 | W230: 0 | X230: 0 | Y230: 64.8 | AB230: 01/01/0001 | AC230: 0 | AD230: - | AE230: - | AI230: 1
A231: 20260600 | B231: 1800029297 | C231: M000 | D231: 46183 | E231: 46183 | F231: 1 | G231: F807 | H231: 1750 | I231: 1-F807-1750 | J231: 6 | K231: 20602491073 | L231: MEDIC YEM SALUD OCUPACIONAL SAC | M231: 0 | N231: 27.88 | P231: 5.02 | R231: 0 | S231: 0 | T231: 0 | U231: 0 | V231: 0 | W231: 0 | X231: 0 | Y231: 32.9 | AB231: 01/01/0001 | AC231: 0 | AD231: - | AE231: - | AI231: 1
A232: 20260600 | B232: 1800029298 | C232: M000 | D232: 46183 | E232: 46183 | F232: 1 | G232: F807 | H232: 1751 | I232: 1-F807-1751 | J232: 6 | K232: 20170717261 | L232: RUMI IMPORT S A | M232: 0 | N232: 86.44 | P232: 15.56 | R232: 0 | S232: 0 | T232: 0 | U232: 0 | V232: 0 | W232: 0 | X232: 0 | Y232: 102 | AB232: 01/01/0001 | AC232: 0 | AD232: - | AE232: - | AI232: 1
A233: 20260600 | B233: 1800029422 | C233: M000 | D233: 46184 | E233: 46184 | F233: 1 | G233: F807 | H233: 1752 | I233: 1-F807-1752 | J233: 6 | K233: 20118798539 | L233: INDUSTRIAL DON MARTIN S A C | M233: 0 | N233: 193.65 | P233: 34.85 | R233: 0 | S233: 0 | T233: 0 | U233: 0 | V233: 0 | W233: 0 | X233: 0 | Y233: 228.5 | AB233: 01/01/0001 | AC233: 0 | AD233: - | AE233: - | AI233: 1
A234: 20260600 | B234: 1800029423 | C234: M000 | D234: 46184 | E234: 46184 | F234: 1 | G234: F807 | H234: 1753 | I234: 1-F807-1753 | J234: 6 | K234: 20551254659 | L234: HASHEM JIREH LOGISTIC S A C | M234: 0 | N234: 96.1 | P234: 17.3 | R234: 0 | S234: 0 | T234: 0 | U234: 0 | V234: 0 | W234: 0 | X234: 0 | Y234: 113.4 | AB234: 01/01/0001 | AC234: 0 | AD234: - | AE234: - | AI234: 1
A235: 20260600 | B235: 1800029424 | C235: M000 | D235: 46184 | E235: 46184 | F235: 1 | G235: F807 | H235: 1754 | I235: 1-F807-1754 | J235: 6 | K235: 10727397707 | L235: GIAN MORALES JIMENEZ | M235: 0 | N235: 43.05 | P235: 7.75 | R235: 0 | S235: 0 | T235: 0 | U235: 0 | V235: 0 | W235: 0 | X235: 0 | Y235: 50.8 | AB235: 01/01/0001 | AC235: 0 | AD235: - | AE235: - | AI235: 1
A236: 20260600 | B236: 1800029425 | C236: M000 | D236: 46184 | E236: 46184 | F236: 1 | G236: F807 | H236: 1755 | I236: 1-F807-1755 | J236: 6 | K236: 20553073694 | L236: MULTICONTAINER PER SAC | M236: 0 | N236: 67.79 | P236: 12.21 | R236: 0 | S236: 0 | T236: 0 | U236: 0 | V236: 0 | W236: 0 | X236: 0 | Y236: 80 | AB236: 01/01/0001 | AC236: 0 | AD236: - | AE236: - | AI236: 1
A237: 20260600 | B237: 1800029577 | C237: M000 | D237: 46185 | E237: 46185 | F237: 1 | G237: F807 | H237: 1756 | I237: 1-F807-1756 | J237: 6 | K237: 20614536072 | L237: LMBEAUTY E I R L | M237: 0 | N237: 30.34 | P237: 5.46 | R237: 0 | S237: 0 | T237: 0 | U237: 0 | V237: 0 | W237: 0 | X237: 0 | Y237: 35.8 | AB237: 01/01/0001 | AC237: 0 | AD237: - | AE237: - | AI237: 1
A238: 20260600 | B238: 1800029578 | C238: M000 | D238: 46185 | E238: 46185 | F238: 1 | G238: F807 | H238: 1757 | I238: 1-F807-1757 | J238: 6 | K238: 20101337261 | L238: ROCA PERU SAC | M238: 0 | N238: 81.78 | P238: 14.72 | R238: 0 | S238: 0 | T238: 0 | U238: 0 | V238: 0 | W238: 0 | X238: 0 | Y238: 96.5 | AB238: 01/01/0001 | AC238: 0 | AD238: - | AE238: - | AI238: 1
...

Sheet cortesia
A1: Restaurante | B1: Fecha | C1: Documento | E1: D | F1: ume | G1: nto | I1: TipoCanal | J1: Neto | K1: IGV | L1: Servicios | M1: DescRec | N1: Descuento | O1: Total | P1: TipoPago | Q1: Observacion | R1: Detalle Cortesia
A2: Pardos Bellavista | B2: 46174 | C2: B00805000010131 | D2: 3 | E2: B | F2: 805 | G2: 10131 | H2: 3-B805-10131 | I2: En el Local | J2: 0 | K2: 0 | L2: 0 | M2: 0 | N2: 0 | O2: 0 | P2: TRANSF. GRATUITA | Q2: 15. Prueba de Producto: PRUEBA DE PRODUCTO - AM - AUT LR. JHONNY GUTIERREZ | R2: Prueba de Producto Resta
A3: Pardos Bellavista | B3: 46174 | C3: B00806000024148 | D3: 3 | E3: B | F3: 806 | G3: 24148 | H3: 3-B806-24148 | I3: En el Local | J3: 0 | K3: 0 | L3: 0 | M3: 0 | N3: 0 | O3: 0 | P3: TRANSF. GRATUITA | Q3: 10. ODM Delivery: ODM DELIVERY - POR PRODUCTOS FRIOS - PEDIDO #105021978 | R3: Cortesía Delivery
A4: Pardos Bellavista | B4: 46174 | C4: B00806000024149 | D4: 3 | E4: B | F4: 806 | G4: 24149 | H4: 3-B806-24149 | I4: Para Llevar | J4: 0 | K4: 0 | L4: 0 | M4: 0 | N4: 0 | O4: 0 | P4: TRANSF. GRATUITA | Q4: 10. ODM Delivery: ODM DELIVERY - POR PRODUCTOS FRIOS - PEDIDO #105021978 | R4: Cortesía Delivery
A5: Pardos Bellavista | B5: 46174 | C5: B00806000024164 | D5: 3 | E5: B | F5: 806 | G5: 24164 | H5: 3-B806-24164 | I5: En el Local | J5: 0 | K5: 0 | L5: 0 | M5: 0 | N5: 0 | O5: 0 | P5: TRANSF. GRATUITA | Q5: 15. Prueba de Producto: PRUEBA DE PRODUCTO - PM - LR. MARYCREUZ FARFAN | R5: Prueba de Producto Resta
A6: Pardos Bellavista | B6: 46174 | C6: B00806000024184 | D6: 3 | E6: B | F6: 806 | G6: 24184 | H6: 3-B806-24184 | I6: En el Local | J6: 0 | K6: 0 | L6: 0 | M6: 0 | N6: 0 | O6: 0 | P6: TRANSF. GRATUITA | Q6: 8. Cumpleaños Invitado: CORTESIA - CUMPLEAÑOS INVITADO | R6: Cumpleaños colaborador
A7: Pardos Bellavista | B7: 46175 | C7: B00805000010156 | D7: 3 | E7: B | F7: 805 | G7: 10156 | H7: 3-B805-10156 | I7: En el Local | J7: 0 | K7: 0 | L7: 0 | M7: 0 | N7: 0 | O7: 0 | P7: TRANSF. GRATUITA | Q7: 15. Prueba de Producto: PRUEBA DE PRODUCTO - AM - LR. JHONNY GUTIERREZ | R7: Prueba de Producto Resta
A8: Pardos Bellavista | B8: 46175 | C8: B00805000010182 | D8: 3 | E8: B | F8: 805 | G8: 10182 | H8: 3-B805-10182 | I8: En el Local | J8: 0 | K8: 0 | L8: 0 | M8: 0 | N8: 0 | O8: 0 | P8: TRANSF. GRATUITA | Q8: 16. Reserva Salón: CORTESIA - POR RESERVA EN SALON - MESA 30 | R8: Cortesía salón
A9: Pardos Bellavista | B9: 46175 | C9: B00806000024196 | D9: 3 | E9: B | F9: 806 | G9: 24196 | H9: 3-B806-24196 | I9: En el Local | J9: 0 | K9: 0 | L9: 0 | M9: 0 | N9: 0 | O9: 0 | P9: TRANSF. GRATUITA | Q9: 15. Prueba de Producto: PRUEBA DE PRODUCTO - PM - AUT LR SIULL CHIROQUE | R9: Prueba de Producto Resta
A10: Pardos Bellavista | B10: 46175 | C10: B00806000024226 | D10: 3 | E10: B | F10: 806 | G10: 24226 | H10: 3-B806-24226 | I10: En el Local | J10: 0 | K10: 0 | L10: 0 | M10: 0 | N10: 0 | O10: 0 | P10: TRANSF. GRATUITA | Q10: 13. ODM Salón: ODM - MOT: VECTOR EN ENSALADA FRESCA - MESA 24 | R10: Cortesía salón
A11: Pardos Bellavista | B11: 46175 | C11: B00806000024231 | D11: 3 | E11: B | F11: 806 | G11: 24231 | H11: 3-B806-24231 | I11: En el Local | J11: 0 | K11: 0 | L11: 0 | M11: 0 | N11: 0 | O11: 0 | P11: TRANSF. GRATUITA | Q11: 8. Cumpleaños Invitado: CUMPLEAÑOS INVITADO | R11: Cumpleaños colaborador
A12: Pardos Bellavista | B12: 46176 | C12: B00805000010191 | D12: 3 | E12: B | F12: 805 | G12: 10191 | H12: 3-B805-10191 | I12: En el Local | J12: 0 | K12: 0 | L12: 0 | M12: 0 | N12: 0 | O12: 0 | P12: TRANSF. GRATUITA | Q12: 15. Prueba de Producto: PRUEBA DE PRODUCTO - AM - LR. SIULL CHIROQUE | R12: Prueba de Producto Resta
A13: Pardos Bellavista | B13: 46176 | C13: B00806000024247 | D13: 3 | E13: B | F13: 806 | G13: 24247 | H13: 3-B806-24247 | I13: En el Local | J13: 0 | K13: 0 | L13: 0 | M13: 0 | N13: 0 | O13: 0 | P13: TRANSF. GRATUITA | Q13: 15. Prueba de Producto: PRUEBA DE PRODUCTO - PM - AUT LR JHONNY GUTIERREZ | R13: Prueba de Producto Resta
... A107: Pardos Bellavista | B107: 46196 | C107: B00805000011008 | D107: 3 | E107: B | F107: 805 | G107: 11008 | H107: 3-B805-11008 | I107: En el Local | J107: 0 | K107: 0 | L107: 0 | M107: 0 | N107: 0 | O107: 0 | P107: TRANSF. GRATUITA | Q107: 15. Prueba de Producto: PRUEBA DE PRODUCTO -TURNO AM- LR JHONNY GUTIERREZ | R107: Prueba de Producto Resta
A108: Pardos Bellavista | B108: 46196 | C108: B00805000011010 | D108: 3 | E108: B | F108: 805 | G108: 11010 | H108: 3-B805-11010 | I108: En el Local | J108: 67.2 | K108: 12.08 | L108: 6.72 | M108: 0 | N108: 0 | O108: 86 | P108: TRANSF. GRATUITA | R108: No Indica
A109: Pardos Bellavista | B109: 46196 | C109: B00805000011012 | D109: 3 | E109: B | F109: 805 | G109: 11012 | H109: 3-B805-11012 | I109: En el Local | J109: 32.81 | K109: 5.9 | L109: 3.29 | M109: 0 | N109: 0 | O109: 42 | P109: TRANSF. GRATUITA | R109: No Indica
A110: Pardos Bellavista | B110: 46196 | C110: B00805000011013 | D110: 3 | E110: B | F110: 805 | G110: 11013 | H110: 3-B805-11013 | I110: En el Local | J110: 114.46 | K110: 20.59 | L110: 11.45 | M110: 0 | N110: 0 | O110: 146.5 | P110: TRANSF. GRATUITA | R110: No Indica
A111: Pardos Bellavista | B111: 46196 | C111: B00805000011014 | D111: 3 | E111: B | F111: 805 | G111: 11014 | H111: 3-B805-11014 | I111: En el Local | J111: 49.92 | K111: 8.99 | L111: 4.99 | M111: 0 | N111: 0 | O111: 63.9 | P111: TRANSF. GRATUITA | R111: No Indica
A112: Pardos Bellavista | B112: 46196 | C112: B00805000011015 | D112: 3 | E112: B | F112: 805 | G112: 11015 | H112: 3-B805-11015 | I112: En el Local | J112: 564.07 | K112: 101.55 | L112: 56.38 | M112: 0 | N112: 0 | O112: 722 | P112: TRANSF. GRATUITA | R112: No Indica
A113: Pardos Bellavista | B113: 46196 | C113: B00805000011016 | D113: 3 | E113: B | F113: 805 | G113: 11016 | H113: 3-B805-11016 | I113: En el Local | J113: 74.84 | K113: 13.47 | L113: 7.49 | M113: 0 | N113: 0 | O113: 95.8 | P113: TRANSF. GRATUITA | R113: No Indica
A114: Pardos Bellavista | B114: 46196 | C114: B00805000011017 | D114: 3 | E114: B | F114: 805 | G114: 11017 | H114: 3-B805-11017 | I114: En el Local | J114: 37.04 | K114: 6.66 | L114: 3.7 | M114: 0 | N114: 0 | O114: 47.4 | P114: TRANSF. GRATUITA | R114: No Indica
A115: Pardos Bellavista | B115: 46196 | C115: B00805000011018 | D115: 3 | E115: B | F115: 805 | G115: 11018 | H115: 3-B805-11018 | I115: En el Local | J115: 89.7 | K115: 16.14 | L115: 8.96 | M115: 0 | N115: 0 | O115: 114.8 | P115: TRANSF. GRATUITA | R115: No Indica
A116: Pardos Bellavista | B116: 46196 | C116: B00805000011019 | D116: 3 | E116: B | F116: 805 | G116: 11019 | H116: 3-B805-11019 | I116: En el Local | J116: 67.19 | K116: 12.09 | L116: 6.72 | M116: 0 | N116: 0 | O116: 86 | P116: TRANSF. GRATUITA | R116: No Indica
A117: Pardos Bellavista | B117: 46196 | C117: B00805000011020 | D117: 3 | E117: B | F117: 805 | G117: 11020 | H117: 3-B805-11020 | I117: En el Local | J117: 0 | K117: 0 | L117: 0 | M117: 0 | N117: 0 | O117: 0 | P117: TRANSF. GRATUITA | Q117: 16. Reserva Salón: CORTESIA RESERVA- MESA# 26. | R117: Cortesía salón
A118: Pardos Bellavista | B118: 46196 | C118: B00805000011021 | D118: 3 | E118: B | F118: 805 | G118: 11021 | H118: 3-B805-11021 | I118: En el Local | J118: 96.73 | K118: 17.41 | L118: 9.66 | M118: 0 | N118: 0 | O118: 123.8 | P118: TRANSF. GRATUITA | R118: No Indica
A119: Pardos Bellavista | B119: 46196 | C119: B00805000011022 | D119: 3 | E119: B | F119: 805 | G119: 11022 | H119: 3-B805-11022 | I119: En el Local | J119: 24.83 | K119: 4.47 | L119: 2.48 | M119: 17.12 | N119: 0 | O119: 31.78 | P119: TRANSF. GRATUITA | R119: No Indica
A120: Pardos Bellavista | B120: 46196 | C120: B00805000011030 | D120: 3 | E120: B | F120: 805 | G120: 11030 | H120: 3-B805-11030 | I120: En el Local | J120: 0 | K120: 0 | L120: 0 | M120: 0 | N120: 0 | O120: 0 | P120: TRANSF. GRATUITA | Q120: 15. Prueba de Producto: PRUEBA DE PRODUCTO- POSTRE NUEVO- IN HOUSE- ISABEL MONTENEGRO. | R120: Prueba de Producto Resta
A121: Pardos Bellavista | B121: 46196 | C121: B00806000025375 | D121: 3 | E121: B | F121: 806 | G121: 25375 | H121: 3-B806-25375 | I121: En el Local | J121: 0 | K121: 0 | L121: 0 | M121: 0 | N121: 0 | O121: 0 | P121: TRANSF. GRATUITA | Q121: 15. Prueba de Producto: PRUEBA DE PRODUCTO - PM - LR. Siull Chiroque | R121: Prueba de Producto Resta
A122: Pardos Bellavista | B122: 46196 | C122: B00806000025385 | D122: 3 | E122: B | F122: 806 | G122: 25385 | H122: 3-B806-25385 | I122: En el Local | J122: 0 | K122: 0 | L122: 0 | M122: 0 | N122: 0 | O122: 0 | P122: TRANSF. GRATUITA | Q122: 13. ODM Salón: ODM SALON - MESA 23 - POR PAPAS FRIAS | R122: Cortesía salón
A123: Pardos Bellavista | B123: 46196 | C123: B00806000025386 | D123: 3 | E123: B | F123: 806 | G123: 25386 | H123: 3-B806-25386 | I123: En el Local | J123: 0 | K123: 0 | L123: 0 | M123: 0 | N123: 0 | O123: 0 | P123: TRANSF. GRATUITA | Q123: 13. ODM Salón: ODM - SALON- MESA 17 - PB BRASA FRIO | R123: Cortesía salón
A124: Pardos Bellavista | B124: 46196 | C124: B00807000026876 | D124: 3 | E124: B | F124: 807 | G124: 26876 | H124: 3-B807-26876 | I124: Marketplace | J124: 124.92 | K124: 22.48 | L124: 0 | M124: 6.54 | N124: 6.54 | O124: 147.4 | P124: TRANSF. GRATUITA | Q124: RAPPI: - RAPPI **31018 | R124: No Indica
A125: Pardos Bellavista | B125: 46196 | C125: B00807000026877 | D125: 3 | E125: B | F125: 807 | G125: 26877 | H125: 3-B807-26877 | I125: Marketplace | J125: 31.78 | K125: 5.72 | L125: 0 | M125: 0 | N125: 0 | O125: 37.5 | P125: TRANSF. GRATUITA | Q125: PEYA: - PEDIDOSYA **#2037 | R125: No Indica
A126: Pardos Bellavista | B126: 46196 | C126: B00807000026878 | D126: 3 | E126: B | F126: 807 | G126: 26878 | H126: 3-B807-26878 | I126: Marketplace | J126: 40.68 | K126: 7.32 | L126: 0 | M126: 0 | N126: 0 | O126: 48 | P126: TRANSF. GRATUITA | Q126: RAPPI: - RAPPI **32867 | R126: No Indica
A127: Pardos Bellavista | B127: 46196 | C127: B00807000026879 | D127: 3 | E127: B | F127: 807 | G127: 26879 | H127: 3-B807-26879 | I127: Marketplace | J127: 27.88 | K127: 5.02 | L127: 0 | M127: 0 | N127: 0 | O127: 32.9 | P127: TRANSF. GRATUITA | Q127: PEYA: - PEDIDOSYA **#2038 | R127: No Indica
A128: Pardos Bellavista | B128: 46196 | C128: B00807000026880 | D128: 3 | E128: B | F128: 807 | G128: 26880 | H128: 3-B807-26880 | I128: Marketplace | J128: 27.88 | K128: 5.02 | L128: 0 | M128: 0 | N128: 0 | O128: 32.9 | P128: TRANSF. GRATUITA | Q128: RAPPI: - RAPPI **34622 | R128: No Indica
A129: Pardos Bellavista | B129: 46196 | C129: B00807000026881 | D129: 3 | E129: B | F129: 807 | G129: 26881 | H129: 3-B807-26881 | I129: Marketplace | J129: 92.63 | K129: 16.67 | L129: 0 | M129: 0 | N129: 0 | O129: 109.3 | P129: TRANSF. GRATUITA | Q129: RAPPI: - RAPPI **36044 | R129: No Indica
A130: Pardos Bellavista | B130: 46196 | C130: B00807000026882 | D130: 3 | E130: B | F130: 807 | G130: 26882 | H130: 3-B807-26882 | I130: Marketplace | J130: 55.76 | K130: 10.04 | L130: 0 | M130: 0 | N130: 0 | O130: 65.8 | P130: TRANSF. GRATUITA | Q130: PEYA: - PEDIDOSYA **#2039 | R130: No Indica
A131: Pardos Bellavista | B131: 46197 | C131: B00805000011034 | D131: 3 | E131: B | F131: 805 | G131: 11034 | H131: 3-B805-11034 | I131: En el Local | J131: 0 | K131: 0 | L131: 0 | M131: 0 | N131: 0 | O131: 0 | P131: TRANSF. GRATUITA | Q131: 15. Prueba de Producto: PRUEBA DE PRODUCTO- TURNO AM. LR. SIULL CHIROQUE. | R131: Prueba de Producto Resta
... A133: Pardos Bellavista | B133: 46197 | C133: B00806000025434 | D133: 3 | E133: B | F133: 806 | G133: 25434 | H133: 3-B806-25434 | I133: En el Local | J133: 0 | K133: 0 | L133: 0 | M133: 0 | N133: 0 | O133: 0 | P133: TRANSF. GRATUITA | Q133: 8. Cumpleaños Invitado: CUMPLEAÑOS INVITADO | R133: Cumpleaños colaborador
A134: Pardos Bellavista | B134: 46196 | C134: F00805000000971 | D134: 1 | E134: F | F134: 805 | G134: 971 | H134: 1-F805-971 | I134: En el Local | J134: 55.23 | K134: 9.95 | L134: 5.52 | M134: 0 | N134: 0 | O134: 70.7 | P134: TRANSF. GRATUITA | R134: No Indica

Sheet flujo
A2: 1 | B2: tabla
B4: tipo de documento de pago | E4: tipo de documento de identidad
B5: codigo | C5: descripción | E5: codigo | F5: descripción | G5: Tipo de Dato | H5: Cantidad de Caracteres / Longitud
B6: 1 | C6: Factura | E6: 0 | F6: Otros tipos de documentos (o Doc. Trib. No Domiciliado sin RUC) | G6: Alfanumérico | H6: Hasta 15 caracteres (Longitud máxima)
B7: 3 | C7: Boleta de Venta | E7: 1 | F7: Documento Nacional de Identidad (DNI) | G7: Numérico | H7: 8 caracteres (Longitud exacta)
B8: 7 | C8: Nota de crédito | E8: 4 | F8: Carnet de Extranjería | G8: Alfanumérico | H8: Hasta 12 caracteres (Longitud máxima)
B9: 8 | C9: Nota de débito | E9: 6 | F9: Registro Único de Contriubuyentes (RUC) | G9: Numérico | H9: 11 caracteres (Longitud exacta)
E10: 7 | F10: Pasaporte | G10: Alfanumérico | H10: Hasta 12 caracteres (Longitud máxima)
A12: 2 | B12: validaciones
B15: correcto
B16: si es boleta y el monto total es mayor a 700 soles, el codigo de tipo de identidad debe ser 1
B17: si el codigo de tipo de documento de identidad es 1 no deben ser número iguales y el nombre debe ser distinto a *cliente*
B18: si es boleta y el tipo de identidad es 6, los dos primeros caracteres deben ser 10
B19: si es boleta y el tipo de documento es 4 no deben ser números iguales y el nombre debe ser distinto a *cliente*
B20: Si el codigo de identidad de sap y sunat son iguales es correcto
B21: si los caracteres del tipo de identidad en sap y sunat son iguales es correcto
B22: si el mensaje es *diferencia* y tipo de pago es cortesia y no hay diferencia en la base, igv, otros servicios y total entonces es correcto
B23: si el mensaje es *registro ok* y no hay diferencia en la base, igv, otros servicios, total y tipo de identidad entonces correcto
B24: si la serie y correlativo tienen secuencia según la fecha es correcto
